2025-09-25 19:21:09 - system_errors - ERROR - log:145 - [ERROR_TRACKING] | User:599762196 | System error in telethon_auto_config: No module named 'download_system' | Details:{"error_type": "ModuleNotFoundError", "error_message": "No module named 'download_system'", "traceback": "Traceback (most recent call last):\n  File \"/app/bot/handlers/telethon_management_handler.py\", line 1590, in telethon_auto_config\n    from download_system.core.telethon_manager import AdvancedTelethonClientManager\nModuleNotFoundError: No module named 'download_system'\n"}
2025-09-25 19:47:43 - system_errors - ERROR - log:145 - [ERROR_TRACKING] | User:599762196 | System error in callback_query_handler: 'NoneType' object has no attribute 'reply_text' | Details:{"error_type": "AttributeError", "error_message": "'NoneType' object has no attribute 'reply_text'", "traceback": "Traceback (most recent call last):\n  File \"/app/bot/handlers/telethon_config_handler.py\", line 693, in _create_final_config\n    'api_id': config_data['api_id'],\n              ~~~~~~~~~~~^^^^^^^^^^\nKeyError: 'api_id'\n\nDuring handling of the above exception, another exception occurred:\n\nTraceback (most recent call last):\n  File \"/app/bot/bot_main.py\", line 357, in handle_callback_query\n    await self.telethon_config_handler._handle_config_phone_input(update, context, \"\", {})\n  File \"/app/bot/handlers/telethon_config_handler.py\", line 684, in _handle_config_phone_input\n    await self._create_final_config(update, context, temp_data)\n  File \"/app/bot/handlers/telethon_config_handler.py\", line 745, in _create_final_config\n    await update.message.reply_text(\n          ^^^^^^^^^^^^^^^^^^^^^^^^^\nAttributeError: 'NoneType' object has no attribute 'reply_text'\n", "callback_data": "telethon_skip_phone", "action": "telethon"}
2025-09-25 19:47:46 - system_errors - ERROR - log:145 - [ERROR_TRACKING] | User:599762196 | System error in callback_query_handler: 'NoneType' object has no attribute 'reply_text' | Details:{"error_type": "AttributeError", "error_message": "'NoneType' object has no attribute 'reply_text'", "traceback": "Traceback (most recent call last):\n  File \"/app/bot/handlers/telethon_config_handler.py\", line 693, in _create_final_config\n    'api_id': config_data['api_id'],\n              ~~~~~~~~~~~^^^^^^^^^^\nKeyError: 'api_id'\n\nDuring handling of the above exception, another exception occurred:\n\nTraceback (most recent call last):\n  File \"/app/bot/bot_main.py\", line 357, in handle_callback_query\n    await self.telethon_config_handler._handle_config_phone_input(update, context, \"\", {})\n  File \"/app/bot/handlers/telethon_config_handler.py\", line 684, in _handle_config_phone_input\n    await self._create_final_config(update, context, temp_data)\n  File \"/app/bot/handlers/telethon_config_handler.py\", line 745, in _create_final_config\n    await update.message.reply_text(\n          ^^^^^^^^^^^^^^^^^^^^^^^^^\nAttributeError: 'NoneType' object has no attribute 'reply_text'\n", "callback_data": "telethon_skip_phone", "action": "telethon"}
2025-09-25 19:47:48 - system_errors - ERROR - log:145 - [ERROR_TRACKING] | User:599762196 | System error in callback_query_handler: 'NoneType' object has no attribute 'reply_text' | Details:{"error_type": "AttributeError", "error_message": "'NoneType' object has no attribute 'reply_text'", "traceback": "Traceback (most recent call last):\n  File \"/app/bot/handlers/telethon_config_handler.py\", line 693, in _create_final_config\n    'api_id': config_data['api_id'],\n              ~~~~~~~~~~~^^^^^^^^^^\nKeyError: 'api_id'\n\nDuring handling of the above exception, another exception occurred:\n\nTraceback (most recent call last):\n  File \"/app/bot/bot_main.py\", line 357, in handle_callback_query\n    await self.telethon_config_handler._handle_config_phone_input(update, context, \"\", {})\n  File \"/app/bot/handlers/telethon_config_handler.py\", line 684, in _handle_config_phone_input\n    await self._create_final_config(update, context, temp_data)\n  File \"/app/bot/handlers/telethon_config_handler.py\", line 745, in _create_final_config\n    await update.message.reply_text(\n          ^^^^^^^^^^^^^^^^^^^^^^^^^\nAttributeError: 'NoneType' object has no attribute 'reply_text'\n", "callback_data": "telethon_skip_phone", "action": "telethon"}
